<?xml version="1.0"?>
<robot xmlns:xacro="http://ros.org/wiki/xacro">

    <!-- Linear Actuator Macro -->
    <xacro:macro name="linear_actuator" params="name size parent child axis lower upper meshes_directory">
        <link name="${name}_link">
            <visual>
                <geometry>
                    <mesh filename="file://${meshes_directory}/LA_rail.stl"/>
                </geometry>
                <material name="metal"/>
            </visual>
        </link>

        <link name="${name}_moving_link">
            <visual>
                <geometry>
                    <mesh filename="file://${meshes_directory}/LA_slider.stl"/>
                </geometry>
                <material name="metal"/>
            </visual>
        </link>

        <joint name="${name}_to_moving" type="prismatic">
            <parent link="${parent}"/>
            <child link="${name}_moving_link"/>
            <origin xyz="0 0 0"/>
            <axis xyz="${axis}"/>
            <limit effort="100.0" lower="${lower}" upper="${upper}" velocity="0.5"/>
        </joint>
    </xacro:macro>

    <!-- Revolute Joint Macro -->
    <xacro:macro name="revolute_joint" params="name parent child axis lower upper">
        <joint name="${name}" type="revolute">
            <parent link="${parent}"/>
            <child link="${child}"/>
            <origin xyz="0 0 0"/>
            <axis xyz="${axis}"/>
            <limit effort="50.0" lower="${lower}" upper="${upper}" velocity="1.0"/>
        </joint>
    </xacro:macro>

</robot>